mkdir: cannot create directory ‘/afs/cern.ch/user/a/aborjess/work/public/ML-Optic-Correction/src/non_linear_tests/supervised_learning/htcondor_dataset’: File exists
multiprocessing.pool.RemoteTraceback: 
"""
Traceback (most recent call last):
  File "/afs/cern.ch/user/a/aborjess/work/public/miniconda3/lib/python3.9/multiprocessing/pool.py", line 125, in worker
    result = (True, func(*args, **kwds))
  File "/afs/cern.ch/user/a/aborjess/work/public/miniconda3/lib/python3.9/multiprocessing/pool.py", line 48, in mapstar
    return list(map(*args))
  File "/afs/cern.ch/user/a/aborjess/work/public/ML-Optic-Correction/src/non_linear_tests/supervised_learning/create_dataset.py", line 344, in create_dataset
    create_sample(sample_id, sample_seed, dataset_name)
  File "/afs/cern.ch/user/a/aborjess/work/public/ML-Optic-Correction/src/non_linear_tests/supervised_learning/create_dataset.py", line 33, in create_sample
    with MAD(mad_path = r"/afs/cern.ch/user/a/aborjess/work/public/mad-linux-0.9.7-pre", debug=True) as mad:
  File "/afs/cern.ch/user/a/aborjess/work/public/miniconda3/lib/python3.9/site-packages/pymadng/madp_object.py", line 74, in __init__
    self.__process = mad_process(mad_path, py_name, debug)
  File "/afs/cern.ch/user/a/aborjess/work/public/miniconda3/lib/python3.9/site-packages/pymadng/madp_pymad.py", line 65, in __init__
    raise OSError(f"Unsuccessful starting of {mad_path} process")
OSError: Unsuccessful starting of /afs/cern.ch/user/a/aborjess/work/public/mad-linux-0.9.7-pre process
"""

The above exception was the direct cause of the following exception:

Traceback (most recent call last):
  File "/afs/cern.ch/user/a/aborjess/work/public/ML-Optic-Correction/src/non_linear_tests/supervised_learning/HTCondor_submit/Job.create_only_triplet_0/exec_create_dataset.py", line 13, in <module>
    create_dataset.main()
  File "/afs/cern.ch/user/a/aborjess/work/public/ML-Optic-Correction/src/non_linear_tests/supervised_learning/create_dataset.py", line 23, in main
    pool.map(create_dataset, args)
  File "/afs/cern.ch/user/a/aborjess/work/public/miniconda3/lib/python3.9/multiprocessing/pool.py", line 364, in map
    return self._map_async(func, iterable, mapstar, chunksize).get()
  File "/afs/cern.ch/user/a/aborjess/work/public/miniconda3/lib/python3.9/multiprocessing/pool.py", line 771, in get
    raise self._value
OSError: Unsuccessful starting of /afs/cern.ch/user/a/aborjess/work/public/mad-linux-0.9.7-pre process
